<?xml version="1.0" ?>
<!-- =================================================================================== -->
<!-- |    This document was autogenerated by xmacro4sdf from model.sdf.xmacro          | -->
<!-- |    EDITING THIS FILE BY HAND IS NOT RECOMMENDED                                 | -->
<!-- =================================================================================== -->
<sdf version="1.7">
	<!--include defination-->
	<!--wheelchair model-->
	<model name="wheelchair">
		<self_collide>false</self_collide>
		<pose>0 0 0.2 0 0 0</pose>
		<link name="base_footprint"/>
		<joint name="base_to_chassis" type="fixed">
			<pose>0 0 0.076 0 0 0</pose>
			<parent>base_footprint</parent>
			<child>base_link</child>
		</joint>
		<link name="base_link">
			<inertial>
				<pose>-0.1 0 0.1 0 0 0</pose>
				<mass>46.2</mass>
				<inertia>
					<ixx>1.55925</ixx>
					<ixy>0</ixy>
					<ixz>0</ixz>
					<iyy>1.55925</iyy>
					<iyz>0</iyz>
					<izz>1.55925</izz>
				</inertia>
			</inertial>
			<collision name="base_link_collision">
				<pose>0 0 0 0 0 0</pose>
				<geometry>
					<mesh>
						<uri>model://wheelchair/meshes/base/tugbot_simp.stl</uri>
					</mesh>
				</geometry>
			</collision>
			<visual name="base_link_visual">
				<pose>0 0 0 0 0 0</pose>
				<geometry>
					<mesh>
						<uri>model://wheelchair/meshes/base/tugbot_simp.dae</uri>
					</mesh>
				</geometry>
			</visual>
			<visual name="light_link_visual">
				<pose>-0.1 0 0.1945 0 1.57079632679 0</pose>
				<geometry>
					<mesh>
						<uri>model://wheelchair/meshes/light_link/light_led.stl</uri>
					</mesh>
				</geometry>
				<material>
					<ambient>0.0 0.0 0 1</ambient>
					<diffuse>0.0 0.0 0 1</diffuse>
					<specular>0 0 0 1</specular>
					<emissive>0 1 0 1</emissive>
				</material>
			</visual>
			<visual name="warnign_light_visual">
				<pose>-0.099 0 0.195 0 1.57079632679 0</pose>
				<geometry>
					<mesh>
						<uri>model://wheelchair/meshes/light_link/light.stl</uri>
					</mesh>
				</geometry>
				<material>
					<ambient>0.1 0.05 0 0.5</ambient>
					<diffuse>1 0.5 0 0.5</diffuse>
					<specular>1 0.5 0 0.5</specular>
					<emissive>1 0.5 0 0.5</emissive>
				</material>
			</visual>
		</link>
		<!--wheels-->
		<joint name="wheel_front_joint" type="fixed">
			<pose relative_to="base_link">0.145 0 0.0345 1.570796327 0 0</pose>
			<parent>base_link</parent>
			<child>wheel_front</child>
		</joint>
		<link name="wheel_front">
			<pose relative_to="wheel_front_joint">0 0 0 0 0 0</pose>
			<inertial>
				<pose>0 0 0 0 0 0</pose>
				<mass>0.1</mass>
				<inertia>
					<ixx>2.083333333333334e-05</ixx>
					<ixy>0</ixy>
					<ixz>0</ixz>
					<iyy>2.083333333333334e-05</iyy>
					<iyz>0</iyz>
					<izz>3.125000000000001e-05</izz>
				</inertia>
			</inertial>
			<collision name="wheel_front_collision">
				<pose>0 0 0 0 0 0</pose>
				<geometry>
					<sphere>
						<radius>0.025</radius>
					</sphere>
				</geometry>
				<max_contacts>2</max_contacts>
				<surface>
					<contact>
						<ode>
							<kp>1000000.0</kp>
							<kd>1</kd>
							<min_depth>0.01</min_depth>
							<max_vel>1</max_vel>
						</ode>
					</contact>
					<friction>
						<ode>
							<mu>0.1</mu>
							<mu2>0.1</mu2>
						</ode>
					</friction>
				</surface>
			</collision>
		</link>
		<joint name="wheel_back_joint" type="fixed">
			<pose relative_to="base_link">-0.225 0 0.035 1.570796327 0 0</pose>
			<parent>base_link</parent>
			<child>wheel_back</child>
		</joint>
		<link name="wheel_back">
			<pose relative_to="wheel_back_joint">0 0 0 0 0 0</pose>
			<inertial>
				<pose>0 0 0 0 0 0</pose>
				<mass>0.1</mass>
				<inertia>
					<ixx>3.583333333333334e-05</ixx>
					<ixy>0</ixy>
					<ixz>0</ixz>
					<iyy>3.583333333333334e-05</iyy>
					<iyz>0</iyz>
					<izz>6.125000000000001e-05</izz>
				</inertia>
			</inertial>
			<collision name="wheel_back_collision">
				<pose>0 0 0 0 0 0</pose>
				<geometry>
					<sphere>
						<radius>0.035</radius>
					</sphere>
				</geometry>
				<max_contacts>2</max_contacts>
				<surface>
					<contact>
						<ode>
							<kp>1000000.0</kp>
							<kd>1</kd>
							<min_depth>0.01</min_depth>
							<max_vel>1</max_vel>
						</ode>
					</contact>
					<friction>
						<ode>
							<mu>0.1</mu>
							<mu2>0.1</mu2>
						</ode>
					</friction>
				</surface>
			</collision>
		</link>
		<joint name="wheel_left_joint" type="revolute">
			<pose relative_to="base_link">0 0.257 0.195 -1.570796327 0 0</pose>
			<parent>base_link</parent>
			<child>wheel_left</child>
			<axis>
				<xyz>0 0 1</xyz>
				<limit>
					<effort>100</effort>
					<velocity>100</velocity>
					<lower>-1.79769e+308</lower>
					<upper>1.79769e+308</upper>
				</limit>
				<dynamics>
					<damping>3.0</damping>
					<friction>0.5</friction>
				</dynamics>
			</axis>
		</joint>
		<link name="wheel_left">
			<pose relative_to="wheel_left_joint">0 0 0 0 0 0</pose>
			<inertial>
				<pose>0 0 0 0 0 0</pose>
				<mass>0.1</mass>
				<inertia>
					<ixx>0.0009714583333333334</ixx>
					<ixy>0</ixy>
					<ixz>0</ixz>
					<iyy>0.0009714583333333334</iyy>
					<iyz>0</iyz>
					<izz>0.0019012500000000004</izz>
				</inertia>
			</inertial>
			<collision name="wheel_left_collision">
				<pose>0 0 0 0 0 0</pose>
				<geometry>
					<cylinder>
						<radius>0.195</radius>
						<length>0.05</length>
					</cylinder>
				</geometry>
				<max_contacts>5</max_contacts>
				<surface>
					<contact>
						<ode>
							<kp>1000000.0</kp>
							<kd>1</kd>
							<min_depth>0.01</min_depth>
							<max_vel>1</max_vel>
						</ode>
					</contact>
					<friction>
						<ode>
							<mu>1.16</mu>
							<mu2>10</mu2>
							<fdir1>1 0 0</fdir1>
						</ode>
					</friction>
				</surface>
			</collision>
			<visual name="wheel_left_visual">
				<pose>0 0 -0.03 0 0 0</pose>
				<geometry>
					<mesh>
						<scale>0.98 0.98 1.0</scale>
						<uri>model://wheelchair/meshes/wheel/wheel.dae</uri>
					</mesh>
				</geometry>
			</visual>
		</link>
		<joint name="wheel_right_joint" type="revolute">
			<pose relative_to="base_link">0 -0.257 0.195 1.570796327 0 0</pose>
			<parent>base_link</parent>
			<child>wheel_right</child>
			<axis>
				<xyz>0 0 -1</xyz>
				<limit>
					<effort>100</effort>
					<velocity>100</velocity>
					<lower>-1.79769e+308</lower>
					<upper>1.79769e+308</upper>
				</limit>
				<dynamics>
					<damping>3.0</damping>
					<friction>0.5</friction>
				</dynamics>
			</axis>
		</joint>
		<link name="wheel_right">
			<pose relative_to="wheel_right_joint">0 0 0 0 0 0</pose>
			<inertial>
				<pose>0 0 0 0 0 0</pose>
				<mass>0.1</mass>
				<inertia>
					<ixx>0.0009714583333333334</ixx>
					<ixy>0</ixy>
					<ixz>0</ixz>
					<iyy>0.0009714583333333334</iyy>
					<iyz>0</iyz>
					<izz>0.0019012500000000004</izz>
				</inertia>
			</inertial>
			<collision name="wheel_right_collision">
				<pose>0 0 0 0 0 0</pose>
				<geometry>
					<cylinder>
						<radius>0.195</radius>
						<length>0.05</length>
					</cylinder>
				</geometry>
				<max_contacts>5</max_contacts>
				<surface>
					<contact>
						<ode>
							<kp>1000000.0</kp>
							<kd>1</kd>
							<min_depth>0.01</min_depth>
							<max_vel>1</max_vel>
						</ode>
					</contact>
					<friction>
						<ode>
							<mu>1.16</mu>
							<mu2>10</mu2>
							<fdir1>1 0 0</fdir1>
						</ode>
					</friction>
				</surface>
			</collision>
			<visual name="wheel_right_visual">
				<pose>0 0 -0.03 0 0 0</pose>
				<geometry>
					<mesh>
						<scale>0.98 0.98 1.0</scale>
						<uri>model://wheelchair/meshes/wheel/wheel.dae</uri>
					</mesh>
				</geometry>
			</visual>
		</link>
		<!-- camera body, with origin at bottom screw mount -->
		<joint name="left_d435i_bottom_joint" type="fixed">
			<pose relative_to="base_link">0.2 0.2 0.4 1.57 0.1 -0.5</pose>
			<parent>base_link</parent>
			<child>left_bottom_screw_frame</child>
		</joint>
		<link name="left_bottom_screw_frame">
			<pose relative_to="left_d435i_bottom_joint">0 0 0 0 0 0</pose>
		</link>
		<joint name="left_d435i_joint" type="fixed">
			<pose relative_to="left_bottom_screw_frame">0 0.0175 0.0125 0 0 0</pose>
			<parent>left_bottom_screw_frame</parent>
			<child>left_d435i</child>
		</joint>
		<link name="left_d435i">
			<pose relative_to="left_d435i_joint">0 0 0 0 0 0</pose>
			<visual name="visual">
				<pose>-0.0211 -0.0175 0 0 0 1.5707963267948966</pose>
				<geometry>
					<mesh>
						<uri>model://d435i/meshes/d435.dae</uri>
					</mesh>
				</geometry>
			</visual>
			<collision name="collision">
				<pose>-0.008 -0.0175 0 0 0 0</pose>
				<geometry>
					<box>
						<size>0.02505 0.09 0.025</size>
					</box>
				</geometry>
			</collision>
			<inertial>
				<pose>-0.008 -0.0175 0 0 0 0</pose>
				<mass>0.072</mass>
				<inertia>
					<ixx>5.235e-05</ixx>
					<ixy>0</ixy>
					<ixz>0</ixz>
					<iyy>7.515015e-06</iyy>
					<iyz>0</iyz>
					<izz>5.236501499999999e-05</izz>
				</inertia>
			</inertial>
			<!-- Color camera sensor -->
			<sensor name="left_color" type="camera">
				<always_on>1</always_on>
				<update_rate>30</update_rate>
				<camera>
					<optical_frame_id>left_color_optical_frame</optical_frame_id>
					<horizontal_fov>1.2112585008840648</horizontal_fov>
					<image>
						<width>1920</width>
						<height>1080</height>
					</image>
					<clip>
						<near>0.1</near>
						<far>100</far>
					</clip>
					<noise>
						<type>gaussian</type>
						<mean>0.0</mean>
						<stddev>0.007</stddev>
					</noise>
				</camera>
			</sensor>
			<!-- Depth camera sensor -->
			<sensor name="left_depth" type="depth_camera">
				<always_on>1</always_on>
				<update_rate>10</update_rate>
				<camera>
					<optical_frame_id>left_depth_optical_frame</optical_frame_id>
					<horizontal_fov>1.4870205226991686</horizontal_fov>
					<image>
						<width>1280</width>
						<height>720</height>
						<format>R_FLOAT32</format>
					</image>
					<clip>
						<near>0.1</near>
						<far>10.0</far>
					</clip>
				</camera>
			</sensor>
			<!-- IMU sensor -->
			<sensor name="left_imu" type="imu">
				<ignition_frame_id>left_imu_frame</ignition_frame_id>
				<always_on>1</always_on>
				<update_rate>200</update_rate>
			</sensor>
		</link>
		<!-- camera depth joints and links -->
		<joint name="left_depth_joint" type="fixed">
			<pose relative_to="left_d435i">0 0 0 0 0 0</pose>
			<parent>left_d435i</parent>
			<child>left_depth_frame</child>
		</joint>
		<link name="left_depth_frame">
			<pose relative_to="left_depth_joint">0 0 0 0 0 0</pose>
		</link>
		<joint name="left_depth_optical_joint" type="fixed">
			<pose relative_to="left_depth_frame">0 0 0 -1.5707963267948966 0 -1.5707963267948966</pose>
			<parent>left_depth_frame</parent>
			<child>left_depth_optical_frame</child>
		</joint>
		<link name="left_depth_optical_frame">
			<pose relative_to="left_depth_optical_joint">0 0 0 0 0 0</pose>
		</link>
		<!-- camera left IR joints and links (infra1) -->
		<joint name="left_infra1_joint" type="fixed">
			<pose relative_to="left_d435i">0 0 0 0 0 0</pose>
			<parent>left_d435i</parent>
			<child>left_infra1_frame</child>
		</joint>
		<link name="left_infra1_frame">
			<pose relative_to="left_infra1_joint">0 0 0 0 0 0</pose>
			<!-- Infra1 camera sensor -->
			<sensor name="left_infra1" type="camera">
				<always_on>1</always_on>
				<update_rate>30</update_rate>
				<camera>
					<optical_frame_id>left_infra1_optical_frame</optical_frame_id>
					<horizontal_fov>1.57</horizontal_fov>
					<image>
						<width>640</width>
						<height>480</height>
						<format>R8G8B8</format>
					</image>
					<clip>
						<near>0.02</near>
						<far>300</far>
					</clip>
					<noise>
						<type>gaussian</type>
						<mean>0.0</mean>
						<stddev>0.007</stddev>
					</noise>
				</camera>
			</sensor>
		</link>
		<joint name="left_infra1_optical_joint" type="fixed">
			<pose relative_to="left_infra1_frame">0 0 0 -1.5707963267948966 0 -1.5707963267948966</pose>
			<parent>left_infra1_frame</parent>
			<child>left_infra1_optical_frame</child>
		</joint>
		<link name="left_infra1_optical_frame">
			<pose relative_to="left_infra1_optical_joint">0 0 0 0 0 0</pose>
		</link>
		<!-- camera right IR joints and links (infra2) -->
		<joint name="left_infra2_joint" type="fixed">
			<pose relative_to="left_d435i">0 -0.050 0 0 0 0</pose>
			<parent>left_d435i</parent>
			<child>left_infra2_frame</child>
		</joint>
		<link name="left_infra2_frame">
			<pose relative_to="left_infra2_joint">0 0 0 0 0 0</pose>
			<!-- Infra2 camera sensor -->
			<sensor name="left_infra2" type="camera">
				<always_on>1</always_on>
				<update_rate>30</update_rate>
				<camera>
					<optical_frame_id>left_infra2_optical_frame</optical_frame_id>
					<horizontal_fov>1.57</horizontal_fov>
					<image>
						<width>640</width>
						<height>480</height>
						<format>R8G8B8</format>
					</image>
					<clip>
						<near>0.02</near>
						<far>300</far>
					</clip>
					<noise>
						<type>gaussian</type>
						<mean>0.0</mean>
						<stddev>0.007</stddev>
					</noise>
				</camera>
			</sensor>
		</link>
		<joint name="left_infra2_optical_joint" type="fixed">
			<pose relative_to="left_infra2_frame">0 0 0 -1.5707963267948966 0 -1.5707963267948966</pose>
			<parent>left_infra2_frame</parent>
			<child>left_infra2_optical_frame</child>
		</joint>
		<link name="left_infra2_optical_frame">
			<pose relative_to="left_infra2_optical_joint">0 0 0 0 0 0</pose>
		</link>
		<!-- camera color joints and links -->
		<joint name="left_color_joint" type="fixed">
			<pose relative_to="left_d435i">0 0.015 0 0 0 0</pose>
			<parent>left_d435i</parent>
			<child>left_color_frame</child>
		</joint>
		<link name="left_color_frame">
			<pose relative_to="left_color_joint">0 0 0 0 0 0</pose>
		</link>
		<joint name="left_color_optical_joint" type="fixed">
			<pose relative_to="left_color_frame">0 0 0 -1.5707963267948966 0 -1.5707963267948966</pose>
			<parent>left_color_frame</parent>
			<child>left_color_optical_frame</child>
		</joint>
		<link name="left_color_optical_frame">
			<pose relative_to="left_color_optical_joint">0 0 0 0 0 0</pose>
		</link>
		<!-- camera imu joints and links -->
		<joint name="left_imu_joint" type="fixed">
			<pose relative_to="left_d435i">-0.01174 -0.00552 0.0051 0 0 0</pose>
			<parent>left_d435i</parent>
			<child>left_imu_frame</child>
		</joint>
		<link name="left_imu_frame">
			<pose relative_to="left_imu_joint">0 0 0 0 0 0</pose>
		</link>
		<!-- IMU optical frame for accelerometer -->
		<joint name="left_accel_joint" type="fixed">
			<pose relative_to="left_imu_frame">0 0 0 0 0 0</pose>
			<parent>left_imu_frame</parent>
			<child>left_accel_frame</child>
		</joint>
		<link name="left_accel_frame">
			<pose relative_to="left_accel_joint">0 0 0 0 0 0</pose>
		</link>
		<joint name="left_accel_optical_joint" type="fixed">
			<pose relative_to="left_accel_frame">0 0 0 -1.5707963267948966 0 -1.5707963267948966</pose>
			<parent>left_accel_frame</parent>
			<child>left_accel_optical_frame</child>
		</joint>
		<link name="left_accel_optical_frame">
			<pose relative_to="left_accel_optical_joint">0 0 0 0 0 0</pose>
		</link>
		<!-- IMU optical frame for gyroscope -->
		<joint name="left_gyro_joint" type="fixed">
			<pose relative_to="left_imu_frame">0 0 0 0 0 0</pose>
			<parent>left_imu_frame</parent>
			<child>left_gyro_frame</child>
		</joint>
		<link name="left_gyro_frame">
			<pose relative_to="left_gyro_joint">0 0 0 0 0 0</pose>
		</link>
		<joint name="left_gyro_optical_joint" type="fixed">
			<pose relative_to="left_gyro_frame">0 0 0 -1.5707963267948966 0 -1.5707963267948966</pose>
			<parent>left_gyro_frame</parent>
			<child>left_gyro_optical_frame</child>
		</joint>
		<link name="left_gyro_optical_frame">
			<pose relative_to="left_gyro_optical_joint">0 0 0 0 0 0</pose>
		</link>
		<!-- <xmacro_block name="d435i" prefix="right_" parent="base_link" pose="0.2 -0.2 0.4 1.57 0.1 0.5"/> -->
		<joint name="livox_joint" type="fixed">
			<pose relative_to="base_link">-0.16 0.0 0.48 0.5235987755982988 0.0 1.5707963267948966</pose>
			<parent>base_link</parent>
			<child>mid360</child>
		</joint>
		<link name="mid360">
			<pose relative_to="livox_joint">0.0 0.0 0.0 0 0 0</pose>
			<inertial>
				<pose>0 0 0.02 0 0 0</pose>
				<mass>0.005</mass>
				<inertia>
					<ixx>2.6666666666666664e-06</ixx>
					<ixy>0</ixy>
					<ixz>0</ixz>
					<iyy>2.6666666666666664e-06</iyy>
					<iyz>0</iyz>
					<izz>4.000000000000001e-06</izz>
				</inertia>
			</inertial>
			<visual name="visual">
				<pose>0.0 0.0 0.0 0 0 3.141592653589793</pose>
				<geometry>
					<mesh>
						<uri>model://mid360/meshes/mid360.dae</uri>
					</mesh>
				</geometry>
			</visual>
			<sensor name="mid360_imu" type="imu">
				<ignition_frame_id>mid360</ignition_frame_id>
				<always_on>1</always_on>
				<update_rate>200</update_rate>
				<visualize>true</visualize>
			</sensor>
			<sensor name="mid360_lidar" type="gpu_lidar">
				<ignition_frame_id>mid360</ignition_frame_id>
				<pose>0 0 0.03 0 0 0</pose>
				<always_on>true</always_on>
				<visualize>true</visualize>
				<update_rate>20.0</update_rate>
				<ray>
					<scan>
						<horizontal>
							<samples>1875.0</samples>
							<resolution>1.0</resolution>
							<min_angle>0</min_angle>
							<max_angle>6.2831852</max_angle>
						</horizontal>
						<vertical>
							<samples>32</samples>
							<min_angle>-0.12217304764</min_angle>
							<max_angle>0.90757121104</max_angle>
						</vertical>
					</scan>
					<range>
						<min>0.1</min>
						<max>40.0</max>
					</range>
				</ray>
				<noise>
					<type>gaussian</type>
					<mean>0.0</mean>
					<stddev>0.01</stddev>
				</noise>
			</sensor>
		</link>
		<!--diff drive plugin-->
		<plugin filename="ignition-gazebo-diff-drive-system" name="ignition::gazebo::systems::DiffDrive">
			<left_joint>wheel_left_joint</left_joint>
			<right_joint>wheel_right_joint</right_joint>
			<wheel_separation>0.5605</wheel_separation>
			<wheel_radius>0.195</wheel_radius>
			<odom_publish_frequency>20</odom_publish_frequency>
			<frame_id>odom</frame_id>
			<child_frame_id>base_link</child_frame_id>
		</plugin>
		<!--pose publisher plugin-->
		<plugin filename="ignition-gazebo-pose-publisher-system" name="ignition::gazebo::systems::PosePublisher">
			<publish_link_pose>true</publish_link_pose>
			<publish_collision_pose>false</publish_collision_pose>
			<publish_visual_pose>false</publish_visual_pose>
			<publish_sensor_pose>false</publish_sensor_pose>
			<publish_nested_model_pose>true</publish_nested_model_pose>
			<update_frequency>20</update_frequency>
		</plugin>
		<!--joint state publisher plugin-->
		<plugin filename="ignition-gazebo-joint-state-publisher-system" name="ignition::gazebo::systems::JointStatePublisher">
    </plugin>
	</model>
</sdf>

