<?xml version="1.0"?>
<sdf version="1.7">
  <xmacro_define_block name="wheelchair_wheel_caster" params="prefix parent pose radius">
    <joint name="wheel_${prefix}_joint" type="fixed">
      <pose relative_to="${parent}">${pose}</pose>
      <parent>${parent}</parent>
      <child>wheel_${prefix}</child>
    </joint>
    <link name="wheel_${prefix}">
      <pose relative_to="wheel_${prefix}_joint">0 0 0 0 0 0</pose>
      <inertial>
        <pose>0 0 0 0 0 0</pose>
        <xmacro_block name="inertia_cylinder" m="0.1" r="${radius}" l="0.025"/>
      </inertial>
      <collision name="wheel_${prefix}_collision">
        <pose>0 0 0 0 0 0</pose>
        <xmacro_block name="geometry_sphere" r="${radius}"/>
        <max_contacts>2</max_contacts>
        <surface>
          <contact>
            <ode>
              <kp>1000000.0</kp>
              <kd>1</kd>
              <min_depth>0.01</min_depth>
              <max_vel>1</max_vel>
            </ode>
          </contact>
          <friction>
            <ode>
              <mu>0.1</mu>
              <mu2>0.1</mu2>
            </ode>
          </friction>
        </surface>
      </collision>
    </link>
  </xmacro_define_block>

  <!--驱动轮宏定义-->
  <xmacro_define_block name="wheelchair_wheel_drive" params="prefix parent pose axis_direction">
    <joint name="wheel_${prefix}_joint" type="revolute">
      <pose relative_to="${parent}">${pose}</pose>
      <parent>${parent}</parent>
      <child>wheel_${prefix}</child>
      <axis>
        <xyz>${axis_direction}</xyz>
        <limit>
          <effort>100</effort>
          <velocity>100</velocity>
          <lower>-1.79769e+308</lower>
          <upper>1.79769e+308</upper>
        </limit>
        <dynamics>
          <damping>3.0</damping>
          <friction>0.5</friction>
        </dynamics>
      </axis>
    </joint>
    <link name="wheel_${prefix}">
      <pose relative_to="wheel_${prefix}_joint">0 0 0 0 0 0</pose>
      <inertial>
        <pose>0 0 0 0 0 0</pose>
        <xmacro_block name="inertia_cylinder" m="0.1" r="0.195" l="0.05"/>
      </inertial>
      <collision name="wheel_${prefix}_collision">
        <pose>0 0 0 0 0 0</pose>
        <xmacro_block name="geometry_cylinder" m="0.1" r="0.195" l="0.05"/>
        <max_contacts>5</max_contacts>
        <surface>
          <contact>
            <ode>
              <kp>1000000.0</kp>
              <kd>1</kd>
              <min_depth>0.01</min_depth>
              <max_vel>1</max_vel>
            </ode>
          </contact>
          <friction>
            <ode>
              <mu>1.16</mu>
              <mu2>10</mu2>
              <fdir1>1 0 0</fdir1>
            </ode>
          </friction>
        </surface>
      </collision>
      <visual name="wheel_${prefix}_visual">
        <pose>0 0 -0.03 0 0 0</pose>
        <geometry>
          <mesh>
            <scale>0.98 0.98 1.0</scale>
            <uri>model://wheelchair/meshes/wheel/wheel.dae</uri>
          </mesh>
        </geometry>
      </visual>
    </link>
  </xmacro_define_block>
</sdf>